<?xml version="1.0"?>
<robot name="my_robot">

    <!-- COLORES GAZEBO -->

    <material name="green">
        <color rgba="0 0.8 0 1"/>
    </material>

    <material name="grey">
        <color rgba="0.75 0.75 0.75 1"/>
    </material>

    <material name="red">
        <color rgba="0.0 0 0 1"/>
    </material>

    <material name="blue">
        <color rgba="0 0 0.8 1"/>
    </material>

    <material name="white">
        <color rgba="1.0 1.0 1.0 1"/>
    </material>

    <material name="black">
        <color rgba="0.0 0.0 0.0 1"/>
    </material>


    <!-- CUERPO ROBOT SIMULACION-->

    <link name="base_link">
        <visual>
        <origin rpy="0.068 0 0" xyz="0 -0.15 0.2"/>
        <geometry>
            <mesh filename="package://mis_modelos_robots/meshes/robot_gazebo/base_link.dae"/>
        </geometry>
        </visual>

        <collision>
            <origin rpy="0.068 0 0" xyz="0 -0.15 0.2"/>
            <geometry>
                <mesh filename="package://mis_modelos_robots/meshes/robot_gazebo/base_link.dae"/>
            </geometry>
        </collision>
        
        <inertial>
            <mass value="0.3"/>
            <origin xyz="0 0 0"/>
            <inertia ixx="0.016" ixy="0.0" ixz="0.0" iyy="0.01" iyz="0.0" izz="0.025"/>
        </inertial>
    </link>

    <gazebo reference="base_link">
      <mu1>0.3</mu1>
      <mu2>0.3</mu2>
      <sensor name="bumpers" type="contact">
         <always_on>1</always_on>
         <update_rate>50.0</update_rate>
         <visualize>true</visualize>
         <contact>
            <collision>base_footprint_collision_base_link</collision>
         </contact>
      </sensor>
    </gazebo>


    <!-- RUEDA FRONTAL IZQUIERDA -->

    <link name="left_wheel">
        <visual>
            <origin rpy="0 0 0" xyz="0 0 0.0"/>
            <geometry>
                <mesh filename="package://mis_modelos_robots/meshes/robot_gazebo/front_wheels.dae"/>
            </geometry>
        </visual>

        <collision>
            <origin rpy="0 0 0" xyz="0 0 0.0"/>
            <geometry>
                <mesh filename="package://mis_modelos_robots/meshes/robot_gazebo/front_wheels.dae"/>
            </geometry>
        </collision>

        <inertial>
            <mass value="0.01"/>
            <origin xyz="0 0 0"/>
            <inertia ixx="4.275e-05" ixy="0.0" ixz="0.0" iyy="4.275e-05" iyz="0.0" izz="7.2e-05"/>
        </inertial>
    </link>

    <gazebo reference="left_wheel">
        <mu1>1.0</mu1>
        <mu2>1.0</mu2>
        <kp>1000000.0</kp>
        <kd>100.0</kd>
        <minDepth>0.001</minDepth>
        <maxVel>1.0</maxVel>
    </gazebo>


    <joint name="left_wheel_joint" type="continuous">
        <parent link="base_link"/>
        <child link="left_wheel"/>
        <origin xyz="0.295 0 0.12" rpy="0 0 0"/>
        <limit lower="-0.6" upper="0.6" effort="0.1" velocity="0.005"/>
        <axis xyz="1 0 0"/>
    </joint>


    <!-- RUEDA FRONTAL DERECHA -->

    <link name="right_wheel">
        <visual>
            <origin rpy="0 0 0" xyz="0 0 0.0"/>
            <geometry>
                <mesh filename="package://mis_modelos_robots/meshes/robot_gazebo/front_wheels.dae"/>
            </geometry>
        </visual>

        <collision>
            <origin rpy="0 0 0" xyz="0 0 0.0"/>
            <geometry>
                <mesh filename="package://mis_modelos_robots/meshes/robot_gazebo/front_wheels.dae"/>
            </geometry>
        </collision>

        <inertial>
            <mass value="0.01"/>
            <origin xyz="0 0 0"/>
            <inertia ixx="4.275e-05" ixy="0.0" ixz="0.0" iyy="4.275e-05" iyz="0.0" izz="7.2e-05"/>
        </inertial>
    </link>

    <gazebo reference="right_wheel">
        <mu1>1.0</mu1>
        <mu2>1.0</mu2>
        <kp>1000000.0</kp>
        <kd>100.0</kd>
        <minDepth>0.001</minDepth>
        <maxVel>1.0</maxVel>
    </gazebo>


	<joint name="right_wheel_joint" type="continuous">
        <parent link="base_link"/>
        <child link="right_wheel"/>
        <origin xyz="-0.295 0 0.12" rpy="0 0 0"/>
        <limit lower="-0.6" upper="0.6" effort="0.1" velocity="0.005"/>
        <axis xyz="1 0 0"/>
    </joint>


    <!-- RUEDA TRASERA -->

    <link name="back_wheel">
        <visual>
            <origin rpy="0 0 0" xyz="0 0 0.0"/>
            <geometry>
                <mesh filename="package://mis_modelos_robots/meshes/robot_gazebo/back_wheel.dae"/>
            </geometry>
        </visual>

        <collision>
            <origin rpy="0 0 0" xyz="0 0 0.0"/>
            <geometry>
                <mesh filename="package://mis_modelos_robots/meshes/robot_gazebo/back_wheel.dae"/>
            </geometry>
        </collision>

        <inertial>
            <mass value="0.01"/>
            <origin xyz="0 0 0"/>
            <inertia ixx="2.1070000000000003e-05" ixy="0.0" ixz="0.0" iyy="2.1070000000000003e-05" iyz="0.0" izz="3.2000000000000005e-05"/>
        </inertial>
    </link>

    <gazebo reference="back_wheel">
        <mu1>1.0</mu1>
        <mu2>1.0</mu2>
        <kp>1000000.0</kp>
        <kd>100.0</kd>
        <minDepth>0.001</minDepth>
        <maxVel>1.0</maxVel>
    </gazebo>


	<joint name="back_wheel_joint" type="continuous">
        <parent link="base_link"/>
        <child link="back_wheel"/>
        <origin xyz="0 -0.45 0.065" rpy="0 0 0"/>
        <limit lower="-0.6" upper="0.6" effort="0.1" velocity="0.005"/>
        <axis xyz="1 0 0"/>
    </joint>


    <!-- BASE MOTOR ROTACI0N -->

    <link name="base_energy_motor">
        <visual>
            <origin rpy="0 0 0" xyz="0 0 0.0"/>
            <geometry>
                <mesh filename="package://mis_modelos_robots/meshes/robot_gazebo/base_motor.dae"/>
            </geometry>
        </visual>

        <collision>
            <origin rpy="0 0 0" xyz="0 0 0.0"/>
            <geometry>
                <mesh filename="package://mis_modelos_robots/meshes/robot_gazebo/base_motor.dae"/>
            </geometry>
        </collision>

        <inertial>
            <mass value="0.01"/>
            <origin xyz="0 0 0"/>
            <inertia ixx="2.1070000000000003e-05" ixy="0.0" ixz="0.0" iyy="2.1070000000000003e-05" iyz="0.0" izz="3.2000000000000005e-05"/>
        </inertial>
    </link>

    <gazebo reference="base_energy_motor">
        <mu1>1.0</mu1>
        <mu2>1.0</mu2>
        <kp>1000000.0</kp>
        <kd>100.0</kd>
        <minDepth>0.001</minDepth>
        <maxVel>1.0</maxVel>
    </gazebo>

	<joint name="base_energy_joint" type="continuous">  <!-- tipo continua -->
        <parent link="base_link"/>
        <child link="base_energy_motor"/>
        <origin xyz="0 -0.38 0.18" rpy="0 0 0"/>
        <limit lower="-3.14159277101" upper="3.14159277101" effort="0.1" velocity="0.005"/>
        <axis xyz="0 0 1"/>
    </joint>


    <!-- ROTADOR DEL ROBOT (PARA ENERGIA) -->

    <link name="horizontal_energy_link">
        <visual>
            <origin rpy="0 0 0" xyz="0 0 0.0"/>
            <geometry>
                <mesh filename="package://mis_modelos_robots/meshes/robot_gazebo/horizontal_energy.dae"/>
            </geometry>
        </visual>

        <collision>
            <origin rpy="0 0 0" xyz="0 0 0.0"/>
            <geometry>
                <mesh filename="package://mis_modelos_robots/meshes/robot_gazebo/horizontal_energy.dae"/>
            </geometry>
        </collision>

        <inertial>
            <mass value="0.01"/>
            <origin xyz="0 0 0"/>
            <inertia ixx="2.1070000000000003e-05" ixy="0.0" ixz="0.0" iyy="2.1070000000000003e-05" iyz="0.0" izz="3.2000000000000005e-05"/>
        </inertial>
    </link>

    <gazebo reference="horizontal_energy_link">
        <mu1>1.0</mu1>
        <mu2>1.0</mu2>
        <kp>1000000.0</kp>
        <kd>100.0</kd>
        <minDepth>0.001</minDepth>
        <maxVel>1.0</maxVel>
    </gazebo>


	<joint name="horizontal_energy_joint" type="fixed">  <!-- articulacion fijada-->
        <parent link="base_energy_motor"/>
        <child link="horizontal_energy_link"/>
        <origin xyz="0 0.0 0.30" rpy="0 0 0"/>
    </joint>


    <gazebo>
        <plugin name="gazebo_ros_control" filename="libgazebo_ros_control.so">
            <robotNamespace>/mis_modelos_robots</robotNamespace>
            <legacyModeNS>true<legacyModeNS>
        </plugin>
    </gazebo>

    <transmission name="tran1">
        <type>transmission_interface/SimpleTransmission</type>
        <joint name="horizontal_energy_link">
            <hardwareInterface>harware_interface/EffortJointInterface</hardware_interface>
        </joint>
        <actuator name="motor_energia">
            <mechanicalReduction>1</mechanicalReduction>
        </actuator>
    </transmission>



    <gazebo>
        <plugin filename="libgazebo_ros_diff_drive.so" name="differential_drive_controller">
            <alwaysOn>true</alwaysOn>
            <updateRate>20</updateRate>
            <publishTf> true </publishTf>
            <leftJoint>right_wheel_joint</leftJoint>
            <rightJoint>left_wheel_joint</rightJoint>
            <wheelSeparation>.59</wheelSeparation>
            <wheelDiameter>0.240</wheelDiameter>
            <torque>5.0</torque>
            <commandTopic>/cmd_vel</commandTopic>
            <odometrySource>world</odometrySource> 
            <odometryTopic>/odom</odometryTopic>
            <odometryFrame>/odom</odometryFrame>
            <robotBaseFrame>/base_linkt</robotBaseFrame>
            <publishOdomTF> true </publishOdomTF>
            <publishWheelJointState>true</publishWheelJointState>
            <publishWheelTF>true</publishWheelTF>
            <wheelAcceleration> 0 </wheelAcceleration>
            <wheelTorque> 5.0 </wheelTorque>
            <legacyMode>true</legacyMode>
            <rosDebugLevel> na </rosDebugLevel>
        </plugin>
    </gazebo>


    <!-- SENSOR LASER KOBUKI -->

	<link name="laser_sensor_link">
		<visual>
			<origin rpy="0.0 0 0.0" xyz="0 0 0.0"/>
			<geometry>
				<mesh filename="package://mis_modelos_robots/meshes/kobuki_meshes/sensors/hokuyo.dae"/>
			</geometry>
		</visual>
	</link>


    <joint name="laser_sensor_joint" type="fixed">
      <origin rpy="0.0 0 0" xyz="0 0.218 0.33"/>
      <parent link="base_link"/>
      <child link="laser_sensor_link"/>
	</joint>


    <!-- KOBUKI PLUGIN -->

    <gazebo reference="laser_sensor_link">
        <sensor name="laser_sensor" type="gpu_ray">
            <pose>0 0 0 0 0 0</pose>
            <visualize>false</visualize>
            <update_rate>40</update_rate>
            <ray>
                <scan>
                <horizontal>
                    <samples>720</samples>
                    <resolution>1</resolution>
                    <min_angle>-1.570796</min_angle>
                    <max_angle>1.570796</max_angle>
                    <!--
                    <min_angle>-2.26889</min_angle>
                    <max_angle>2.268899</max_angle>
                    -->
                </horizontal>
                </scan>
                <range>
                <min>0.10</min>
                <max>30.0</max>
                <resolution>0.01</resolution>
                </range>
                <noise>
                <type>gaussian</type>
                <mean>0.0</mean>
                <stddev>0.01</stddev>
                </noise>
            </ray>
            <plugin filename="libgazebo_ros_gpu_laser.so" name="gazebo_ros_head_hokuyo_controller">
                <topicName>/kobuki/laser/scan</topicName>
                <frameName>laser_sensor_link</frameName>
            </plugin>
        </sensor>
    </gazebo>


    <!-- CAMARA ROBOT (RGB)  -->

	<joint name="camera_rgb_joint" type="fixed">
		<origin rpy="0 0 0" xyz="-0.087 0.0205 0.187"/>
		<parent link="base_link"/>
		<child link="camera_rgb_frame"/>
	</joint>
	<link name="camera_rgb_frame"/>

	<joint name="camera_rgb_optical_joint" type="fixed">
		<origin rpy="-1.57079632679 0 -1.57079632679" xyz="0 0    0"/>
		<parent link="camera_rgb_frame"/>
		<child link="camera_rgb_optical_frame"/>
	</joint>
	<link name="camera_rgb_optical_frame"/>


	<joint name="camera_joint" type="fixed">
		<origin rpy="0 0 0" xyz="0.087 0.11 -0.13"/>
		<parent link="camera_rgb_frame"/>
		<child link="camera_link"/>
	</joint>

	<link name="camera_link">
		<visual>
			<origin rpy="0 0 0" xyz="0 0 0"/>
			<geometry>
				<mesh filename="package://mis_modelos_robots/meshes/robot_gazebo/camera.dae"/>
                <!--<mesh filename="package://mis_modelos_robots/meshes/kinect.dae"/> -->
			</geometry>mis_modelos_robots/meshes/robot_gazebo
		</visual>
        <collision>
            <origin rpy="0 0 0" xyz="0 0 0"/>
			<geometry>
                <mesh filename="package://mis_modelos_robots/meshes/robot_gazebo/camera.dae"/>
				<!--<mesh filename="package://mis_modelos_robots/meshes/kinect.dae"/> -->
			</geometry>
        </collision>
        <inertial>
            <mass value="0.01"/>
            <origin xyz="0 0 0"/>
            <inertia ixx="0.0001152600" ixy="0.0" ixz="0.0" iyy="0.0000148934" iyz="0.0" izz="0.0001154654"/>
        </inertial>

	</link>


    <!-- PLUGIN CAMARA -->

    <gazebo reference="camera_link">
        <sensor type="camera" name="camera1">
        <update_rate>30.0</update_rate>
        <camera name="head">
            <horizontal_fov>1.3962634</horizontal_fov>
            <image>
            <width>800</width>
            <height>800</height>
            <format>R8G8B8</format>
            </image>
            <clip>
            <near>0.02</near>
            <far>300</far>
            </clip>
            <noise>
            <type>gaussian</type>

            <mean>0.0</mean>
            <stddev>0.007</stddev>
            </noise>
        </camera>
        <plugin name="camera_controller" filename="libgazebo_ros_camera.so">
            <alwaysOn>true</alwaysOn>
            <updateRate>0.0</updateRate>
            <cameraName>rrbot/camera1</cameraName>
            <imageTopicName>image_raw</imageTopicName>
            <cameraInfoTopicName>camera_info</cameraInfoTopicName>
            <frameName>camera_link</frameName>
            <hackBaseline>0.07</hackBaseline>
            <distortionK1>0.0</distortionK1>
            <distortionK2>0.0</distortionK2>
            <distortionK3>0.0</distortionK3>
            <distortionT1>0.0</distortionT1>
            <distortionT2>0.0</distortionT2>
        </plugin>
        </sensor>
    </gazebo>


</robot>

